Workbook

Sheet Summary
A1: Arbitrage P&L survey — wallets 0x50dA…4eC1C (Ethereum) and G3yf…f1he (Solana)
A2: All values in USD; stablecoins marked at $1; gas/fees priced at daily Coinbase close. Data through 2026-09-27.
A4: Section | B4: Attempts | C4: Successful | D4: Success rate | E4: Gross gain | F4: Fees + gas | G4: Net P&L
A5: Ethereum atomic flash arbs | B5: =COUNTIFS('ETH arbs'!E:E,"atomic flash arb") -> 242 | C5: =COUNTIFS('ETH arbs'!E:E,"atomic flash arb",'ETH arbs'!D:D,"success") -> 159 | D5: =IF(B5=0,0,C5/B5) -> 0.65702479 | E5: =SUMIFS('ETH arbs'!H:H,'ETH arbs'!E:E,"atomic flash arb") -> 1702.5576 | F5: =SUMIFS('ETH arbs'!I:I,'ETH arbs'!E:E,"atomic flash arb") -> 106.8304 | G5: =E5-F5 -> 1595.7272
A6: Solana atomic flash arbs | B6: =COUNTIFS('SOL arbs'!E:E,"atomic flash arb") -> 1273 | C6: =COUNTIFS('SOL arbs'!E:E,"atomic flash arb",'SOL arbs'!D:D,"success") -> 1156 | D6: =IF(B6=0,0,C6/B6) -> 0.90809112 | E6: =SUMIFS('SOL arbs'!H:H,'SOL arbs'!E:E,"atomic flash arb") -> 844.03639 | F6: =SUMIFS('SOL arbs'!I:I,'SOL arbs'!E:E,"atomic flash arb") -> 2.8048193 | G6: =E6-F6 -> 841.23157
A7: Solana atomic wallet arbs | B7: =COUNTIFS('SOL arbs'!E:E,"atomic wallet arb") -> 71 | C7: =COUNTIFS('SOL arbs'!E:E,"atomic wallet arb",'SOL arbs'!D:D,"success") -> 63 | D7: =IF(B7=0,0,C7/B7) -> 0.88732394 | E7: =SUMIFS('SOL arbs'!H:H,'SOL arbs'!E:E,"atomic wallet arb") -> 147.00654 | F7: =SUMIFS('SOL arbs'!I:I,'SOL arbs'!E:E,"atomic wallet arb") -> 0.079617093 | G7: =E7-F7 -> 146.92692
A8: Solana non-atomic swap legs | B8: =COUNTIFS('SOL non-atomic legs'!E:E,"non-atomic leg") -> 7000 | C8: =COUNTIFS('SOL non-atomic legs'!E:E,"non-atomic leg",'SOL non-atomic legs'!D:D,"success") -> 5030 | D8: =IF(B8=0,0,C8/B8) -> 0.71857143 | E8: =SUMIFS('SOL non-atomic legs'!H:H,'SOL non-atomic legs'!E:E,"non-atomic leg") -> 2873.6892 | F8: =SUMIFS('SOL non-atomic legs'!I:I,'SOL non-atomic legs'!E:E,"non-atomic leg") -> 37.356206 | G8: =E8-F8 -> 2836.333
A9: Atomic arbs total | B9: =SUM(B5:B7) -> 1586 | C9: =SUM(C5:C7) -> 1378 | D9: =IF(B9=0,0,C9/B9) -> 0.86885246 | E9: =SUM(E5:E7) -> 2693.6005 | F9: =SUM(F5:F7) -> 109.71484 | G9: =E9-F9 -> 2583.8857
A10: All bot trading (atomic + non-atomic) | B10: =B9+B8 -> 8586 | C10: =C9+C8 -> 6408 | D10: =IF(B10=0,0,C10/B10) -> 0.74633124 | E10: =E9+E8 -> 5567.2897 | F10: =F9+F8 -> 147.07104 | G10: =E10-F10 -> 5420.2187
A12: Swap provider share (successful atomic arbs, both chains)
A13: Provider | B13: ETH | C13: Solana | D13: Total | E13: Share of trades | F13: Gross gain | G13: Share of gain
A14: 0x | B14: =COUNTIFS('ETH arbs'!F:F,"0x",'ETH arbs'!D:D,"success") -> 159 | C14: =COUNTIFS('SOL arbs'!F:F,"0x",'SOL arbs'!D:D,"success") -> 483 | D14: =B14+C14 -> 642 | E14: =D14/SUM($D$14:$D$17) -> 0.46623094 | F14: =SUMIFS('ETH arbs'!H:H,'ETH arbs'!F:F,"0x")+SUMIFS('SOL arbs'!H:H,'SOL arbs'!F:F,"0x") -> 2087.0764 | G14: =F14/SUM($F$14:$F$17) -> 0.77482773
A15: DFlow | B15: =COUNTIFS('ETH arbs'!F:F,"DFlow",'ETH arbs'!D:D,"success") -> 0 | C15: =COUNTIFS('SOL arbs'!F:F,"DFlow",'SOL arbs'!D:D,"success") -> 534 | D15: =B15+C15 -> 534 | E15: =D15/SUM($D$14:$D$17) -> 0.38779956 | F15: =SUMIFS('ETH arbs'!H:H,'ETH arbs'!F:F,"DFlow")+SUMIFS('SOL arbs'!H:H,'SOL arbs'!F:F,"DFlow") -> 328.50335 | G15: =F15/SUM($F$14:$F$17) -> 0.12195697
A16: OKX | B16: =COUNTIFS('ETH arbs'!F:F,"OKX",'ETH arbs'!D:D,"success") -> 0 | C16: =COUNTIFS('SOL arbs'!F:F,"OKX",'SOL arbs'!D:D,"success") -> 124 | D16: =B16+C16 -> 124 | E16: =D16/SUM($D$14:$D$17) -> 0.090050835 | F16: =SUMIFS('ETH arbs'!H:H,'ETH arbs'!F:F,"OKX")+SUMIFS('SOL arbs'!H:H,'SOL arbs'!F:F,"OKX") -> 111.71385 | G16: =F16/SUM($F$14:$F$17) -> 0.041473801
A17: Jupiter | B17: =COUNTIFS('ETH arbs'!F:F,"Jupiter",'ETH arbs'!D:D,"success") -> 0 | C17: =COUNTIFS('SOL arbs'!F:F,"Jupiter",'SOL arbs'!D:D,"success") -> 77 | D17: =B17+C17 -> 77 | E17: =D17/SUM($D$14:$D$17) -> 0.055918664 | F17: =SUMIFS('ETH arbs'!H:H,'ETH arbs'!F:F,"Jupiter")+SUMIFS('SOL arbs'!H:H,'SOL arbs'!F:F,"Jupiter") -> 166.30695 | G17: =F17/SUM($F$14:$F$17) -> 0.061741504
A19: Provider share incl. non-atomic legs (all successful swaps)
A20: Provider | B20: Swaps | C20: Share
A21: 0x | B21: =COUNTIFS('ETH arbs'!F:F,"0x",'ETH arbs'!D:D,"success")+COUNTIFS('SOL arbs'!F:F,"0x",'SOL arbs'!D:D,"success")+COUNTIFS('SOL non-atomic legs'!F:F,"0x",'SOL non-atomic legs'!D:D,"success") -> 649 | C21: =B21/SUM($B$21:$B$25) -> 0.10129546
A22: DFlow | B22: =COUNTIFS('ETH arbs'!F:F,"DFlow",'ETH arbs'!D:D,"success")+COUNTIFS('SOL arbs'!F:F,"DFlow",'SOL arbs'!D:D,"success")+COUNTIFS('SOL non-atomic legs'!F:F,"DFlow",'SOL non-atomic legs'!D:D,"success") -> 555 | C22: =B22/SUM($B$21:$B$25) -> 0.086624005
A23: OKX | B23: =COUNTIFS('ETH arbs'!F:F,"OKX",'ETH arbs'!D:D,"success")+COUNTIFS('SOL arbs'!F:F,"OKX",'SOL arbs'!D:D,"success")+COUNTIFS('SOL non-atomic legs'!F:F,"OKX",'SOL non-atomic legs'!D:D,"success") -> 737 | C23: =B23/SUM($B$21:$B$25) -> 0.11503044
A24: Jupiter | B24: =COUNTIFS('ETH arbs'!F:F,"Jupiter",'ETH arbs'!D:D,"success")+COUNTIFS('SOL arbs'!F:F,"Jupiter",'SOL arbs'!D:D,"success")+COUNTIFS('SOL non-atomic legs'!F:F,"Jupiter",'SOL non-atomic legs'!D:D,"success") -> 1867 | C24: =B24/SUM($B$21:$B$25) -> 0.29140003
A25: Stable.com | B25: =COUNTIFS('ETH arbs'!F:F,"Stable.com",'ETH arbs'!D:D,"success")+COUNTIFS('SOL arbs'!F:F,"Stable.com",'SOL arbs'!D:D,"success")+COUNTIFS('SOL non-atomic legs'!F:F,"Stable.com",'SOL non-atomic legs'!D:D,"success") -> 2599 | C25: =B25/SUM($B$21:$B$25) -> 0.40565007
A27: Notes
A28: Ethereum: every call from the operator to the 7 executor contracts. Gain = stablecoins entering operator+executors from outside in that tx; reverts cost gas only. All 242 swaps routed through 0x AllowanceHolder -> MainnetSettler.
A29: Solana atomic: flash = txs touching Marginfi account EqRkw9…dLmm; wallet = Stable.com + aggregator in one tx without a flash loan. Gain = wallet stablecoin balance change.
A30: Solana non-atomic legs: separate Stable.com and aggregator swaps (two-token swaps only). Net assumes the inventory round-trips; one-sided cross-chain arrivals/bridge transfers are excluded.
A31: OKX label is for program proVF4…WCqX3u (OKX DEX router, inferred). 4 of 8,751 Solana txs could not be fetched.
A32: Not included: ~31 manual Ethereum wallet swaps (~+$365 net, cross-chain USDG loop legs), LayerZero/bridge fees, Polygon/BSC.

Sheet ETH arbs
A1: chain | B1: time_utc | C1: tx | D1: status | E1: category | F1: provider | G1: detail | H1: stable_gain_usd | I1: fee_usd | J1: net_usd
A2: ethereum | B2: 2026-07-31T15:17:11 | C2: 0xc25fea8375d497419a8f6a2d8ff5644ad6dc647272981a15842a7e74b2ca6292 | D2: reverted | E2: atomic flash arb | F2: 0x | G2: legacy executor 0x4443faee | H2: 0 | I2: 2.9757 | J2: =H2-I2 -> -2.9757
A3: ethereum | B3: 2026-07-31T15:26:23 | C3: 0x98ed57eb1d671108618215c6f5863307a7a88c34d0781dca6db373e1b869fec8 | D3: success | E3: atomic flash arb | F3: 0x | G3: legacy executor 0x4443faee | H3: 61.459859 | I3: 5.1815 | J3: =H3-I3 -> 56.278359
A4: ethereum | B4: 2026-07-31T16:04:11 | C4: 0x37982ed0b7213332df183a1a6d44d36d49bc1c3fc550fa3d2e9ea5c264affa58 | D4: success | E4: atomic flash arb | F4: 0x | G4: legacy executor 0x4443faee | H4: 31.106976 | I4: 3.0085 | J4: =H4-I4 -> 28.098476
A5: ethereum | B5: 2026-07-31T16:24:59 | C5: 0x09ad9e721944acd7d2c43e9da91bc85637518d2228810504d8216be3cb312e41 | D5: success | E5: atomic flash arb | F5: 0x | G5: legacy executor 0xa38d5707 | H5: 38.012488 | I5: 1.4934 | J5: =H5-I5 -> 36.519088
A6: ethereum | B6: 2026-07-31T16:28:23 | C6: 0xfbc79a83165c980e7268c72b3f5fe2527879b5b2a51ac99ab73013f7e018a43e | D6: success | E6: atomic flash arb | F6: 0x | G6: legacy executor 0xa38d5707 | H6: 116.03973 | I6: 1.0395 | J6: =H6-I6 -> 115.00024
A7: ethereum | B7: 2026-07-31T16:28:59 | C7: 0x435eb52c76b824be4a5aa95df5dd7b601b17e76836b8ed36e03a11e29fafa29f | D7: success | E7: atomic flash arb | F7: 0x | G7: legacy executor 0xa38d5707 | H7: 38.347575 | I7: 1.9779 | J7: =H7-I7 -> 36.369675
A8: ethereum | B8: 2026-08-01T01:48:47 | C8: 0x3704878416a0d1ca7881c99241e51b94c4f352576789c6ca374b61444c45222a | D8: success | E8: atomic flash arb | F8: 0x | G8: legacy executor 0xa38d5707 | H8: 20.970772 | I8: 0.0928 | J8: =H8-I8 -> 20.877972
A9: ethereum | B9: 2026-08-14T16:05:59 | C9: 0x2e173daad8005a4e931d8eb8c04ed4ba9a82cb1f4e142e98201e4ed8d1458dd5 | D9: success | E9: atomic flash arb | F9: 0x | G9: legacy executor 0x6fa26637 | H9: 2.641642 | I9: 0.1391 | J9: =H9-I9 -> 2.502542
A10: ethereum | B10: 2026-08-15T17:21:35 | C10: 0xe208c8b0475ea3ace877c7df55f7a1c15e3bed066936aa6f06b28fb177b85fbe | D10: reverted | E10: atomic flash arb | F10: 0x | G10: legacy executor 0xc5ad9f7f | H10: 0 | I10: 0.1889 | J10: =H10-I10 -> -0.1889
A11: ethereum | B11: 2026-08-17T16:22:35 | C11: 0x55d77b243ce3cb20a7a50c01140d9423fb8444cd399e4a6d1a44776e55313459 | D11: reverted | E11: atomic flash arb | F11: 0x | G11: legacy executor 0xc5ad9f7f | H11: 0 | I11: 0.3042 | J11: =H11-I11 -> -0.3042
A12: ethereum | B12: 2026-08-17T16:23:47 | C12: 0xa8edc05a27df3ac0f82fb87a8057e1ecc5fe95ff4b2b607019e4604bb6e67b16 | D12: success | E12: atomic flash arb | F12: 0x | G12: legacy executor 0xc5ad9f7f | H12: 5.998063 | I12: 0.2665 | J12: =H12-I12 -> 5.731563
A13: ethereum | B13: 2026-08-17T19:07:47 | C13: 0xedd6e13f30e0efba7b3a183b13a29f4a69b53d7f25d61ff386b41954bfbf0327 | D13: success | E13: atomic flash arb | F13: 0x | G13: legacy executor 0xc5ad9f7f | H13: 6.745077 | I13: 0.1904 | J13: =H13-I13 -> 6.554677
... A243: ethereum | B243: 2026-09-26T22:42:11 | C243: 0x83d92d625ab541976d490abafa91a2b8a45fd3262db75d93d779ca5c70454db9 | D243: success | E243: atomic flash arb | F243: 0x | G243: PYUSD/USDG Morpho dex-first | H243: 3.846601 | I243: 0.2103 | J243: =H243-I243 -> 3.636301

Sheet SOL arbs
A1: chain | B1: time_utc | C1: tx | D1: status | E1: category | F1: provider | G1: detail | H1: stable_gain_usd | I1: fee_usd | J1: net_usd
A2: solana | B2: 2026-08-01T02:31:01 | C2: 9WcRZqvbzJq4L4L1fQk1xtaY1aDG2oaAReEcn8NDFXMF9gjm8S9pWc3sE6AHGyvbWhjJkUkXQcYvAept7iNtpoU | D2: success | E2: atomic flash arb | F2: none | H2: 0 | I2: 1.2210543 | J2: =H2-I2 -> -1.2210543
A3: solana | B3: 2026-08-01T02:48:26 | C3: BDAHYUR4Umh7eWnKqKcnEU4jr42f7XpK2zx5LvCRMdDJpywcJxEGueY8Scv5xWTstURLY8tbpSA6HYRnUCNs9f6 | D3: success | E3: atomic flash arb | F3: Jupiter | G3: USDT +10.0077, USDC +27.9883 | H3: 37.996 | I3: 0.0006997518 | J3: =H3-I3 -> 37.9953
A4: solana | B4: 2026-08-01T03:01:09 | C4: 34f64CexjEZzw6fBZT9iPxRbbkHiJY6KFuxQMe4mTLc73W7UimrB3xMVMnyJPKy4uEizAet2mmzZ5wfr6oV2NB4V | D4: success | E4: atomic flash arb | F4: Jupiter | G4: USDT +4.9012, USDC +11.8396 | H4: 16.740892 | I4: 0.00068695716 | J4: =H4-I4 -> 16.740205
A5: solana | B5: 2026-08-13T10:33:26 | C5: 2VDEgMx1775c4mp5xErpLzUiJzV1xbACXF5n2gU1gNKBUbnL1M7rZWkoSV2HaEaQtyjiD2x1KApP3n191HWe1iSe | D5: success | E5: atomic flash arb | F5: Jupiter | G5: USDC +0.2288 | H5: 0.228797 | I5: 0.00074327613 | J5: =H5-I5 -> 0.22805372
A6: solana | B6: 2026-08-21T09:46:23 | C6: 5PJfBRgTcTzzjNRt9Z7fa1fi6guMMZyfPNqiZXFpWMpuwJUoUJM4jvkUydkZPAsQFDHA8vm4LBumeacJpwTgv4p6 | D6: failed | E6: atomic flash arb | F6: Jupiter | H6: 0 | I6: 0.00094244832 | J6: =H6-I6 -> -0.00094244832
A7: solana | B7: 2026-08-21T09:47:17 | C7: 2UMgq3TLDaQSQ2MUoTmnwjehvD2NeW3W1iEcQQhX3BX8eDR9oi3k9FSpepUE83vRHYXzYoHuhNN8eL8ipTfjATjQ | D7: success | E7: atomic flash arb | F7: Jupiter | G7: PYUSD +1.3644 | H7: 1.364443 | I7: 0.00094244832 | J7: =H7-I7 -> 1.3635006
A8: solana | B8: 2026-08-21T09:49:32 | C8: 4nwRWJPbecGKK4HjWLGBMnWhvTD8PaMAm8oRsdYcjz8HfZq8FaPkcxbav354JMxNfbpx7cjhpMuoSGbG2KZutpmy | D8: success | E8: atomic flash arb | F8: Jupiter | G8: PYUSD +1.2659 | H8: 1.265888 | I8: 0.00094347924 | J8: =H8-I8 -> 1.2649445
A9: solana | B9: 2026-08-21T09:52:09 | C9: 2q91x3sJxrCPcAk9r5wJztguJgReX2WbEvRzDjV1zkpbtXBemc7WSezxEJERvs8XD5DSJMFaFcMzWE7yMebMdY6r | D9: success | E9: atomic flash arb | F9: Jupiter | G9: PYUSD +1.1650 | H9: 1.164965 | I9: 0.00094479132 | J9: =H9-I9 -> 1.1640202
A10: solana | B10: 2026-08-21T10:03:54 | C10: FYz2Bsdh48TYuC4t6rwKZsGboUwSqsxkyjJTn6sk4KhzriX9mQKV81tC6vEXaADvASy4QR8PPs2fXJNDNk5ogTL | D10: success | E10: atomic flash arb | F10: Jupiter | G10: PYUSD +2.0822 | H10: 2.082231 | I10: 0.00095041452 | J10: =H10-I10 -> 2.0812806
A11: solana | B11: 2026-08-21T10:04:52 | C11: 472PXUj4RyNEcREwRbbmZJRTiK4mjFaNNNS4C24TbKpmhqADsv6g5Tx3JLfabYoNCvgKwFpoGLfRhhcofi7ExMHv | D11: success | E11: atomic flash arb | F11: Jupiter | G11: PYUSD +1.5452 | H11: 1.545188 | I11: 0.00095153916 | J11: =H11-I11 -> 1.5442365
A12: solana | B12: 2026-08-21T10:05:56 | C12: 2LSKSBczUGzJn5gd7dzziYu4CZGEgBevWrQFgLYCxRNwBdge5pZNf6Thm8RSEHWEVXGZMFd3GxuzzS4RpSP1gNBs | D12: success | E12: atomic flash arb | F12: Jupiter | G12: PYUSD +1.3852 | H12: 1.385181 | I12: 0.00095285124 | J12: =H12-I12 -> 1.3842281
A13: solana | B13: 2026-08-22T11:01:47 | C13: 5BHHoHFQqNxWc1P4ghGKHN7Tox7eX9nAgY8GyArJ8jBqwPekZPjkVt31vCNpJKXpJzCN9wbtAWoP36V6SbWxXQp | D13: success | E13: atomic flash arb | F13: Jupiter | G13: USDC +1.2528 | H13: 1.252837 | I13: 0.00087918746 | J13: =H13-I13 -> 1.2519578
A14: solana | B14: 2026-08-24T08:47:12 | C14: 5uaD7ft2t4BhikXhXpCokcPTpDtAU8ah74hsCF24vSYjwCVz9HBHART8Ab5aoNeJYaSReZyjP7zfyjExyfY3K6eU | D14: success | E14: atomic flash arb | F14: Jupiter | G14: PYUSD +0.8121 | H14: 0.812115 | I14: 0.00097505244 | J14: =H14-I14 -> 0.81113995
A15: solana | B15: 2026-08-24T08:51:07 | C15: 2aN7orRG1J8v7FJhkwUD7FfEuJzT8mUVcJNZqwWKCg9E8bw6272E8hmW1XkkoWGP2fqxV3fHAYDsg3j7xCzV3Soe | D15: success | E15: atomic flash arb | F15: Jupiter | G15: PYUSD +0.8533 | H15: 0.853309 | I15: 0.00098336592 | J15: =H15-I15 -> 0.85232563
A16: solana | B16: 2026-08-24T08:51:30 | C16: 3Se152jVgfqdR7p7MGPCk6DhEc1DntAk3P9bUHdHuRcNPa9wjd2vmTRjVjjkUXmG5BKfdG2b4RMy3DJgqgDyijzN | D16: success | E16: atomic flash arb | F16: Jupiter | G16: PYUSD +0.7334 | H16: 0.733389 | I16: 0.00098524635 | J16: =H16-I16 -> 0.73240375
A17: solana | B17: 2026-08-24T08:51:49 | C17: 5AXuqy93ih87ta92m89L2MnXqkjwhA6cuaSYj3ZAhCnnALjx3NXTRaYoTESHP1rf4JVa7H53TcbvENEbxgrgpzFv | D17: success | E17: atomic flash arb | F17: Jupiter | G17: PYUSD +0.6807 | H17: 0.680675 | I17: 0.0009857412 | J17: =H17-I17 -> 0.67968926
A18: solana | B18: 2026-08-24T08:52:13 | C18: 3cikqzAXhqJnL51vDBm8znaNDcJBaa2QhqXo1ueqRmDRNCARRKtnNKbb73bFRjoDMP3PZGMDTtDJkSDkqqzvBHnK | D18: success | E18: atomic flash arb | F18: Jupiter | G18: PYUSD +0.8749 | H18: 0.874949 | I18: 0.00097911021 | J18: =H18-I18 -> 0.87396989
... A25: solana | B25: 2026-08-25T09:06:29 | C25: 4YZ6KL8vEVHCn1quHKNjep1kucUfTLS79vH4VfuQUB5DoEXLztfoZbPGWCrpUyA2NFKj6DtW4EQFycCXJbSNUsNG | D25: success | E25: atomic flash arb | F25: Jupiter | G25: PYUSD +1.6717 | H25: 1.671739 | I25: 0.0011115577 | J25: =H25-I25 -> 1.6706274
A26: solana | B26: 2026-08-30T22:26:37 | C26: 3NrUvaL15mntLAmetubLsMAUEax9ygzapDyTBcW7TC75QJuC2kUH9FbTE5CxEbJeJ8a5tgdmyQkMnU1eKmPaR4v8 | D26: failed | E26: atomic flash arb | F26: Jupiter | H26: 0 | I26: 0.0010503653 | J26: =H26-I26 -> -0.0010503653
A27: solana | B27: 2026-08-30T22:55:49 | C27: 5Cs45CRc93YDbm1AiTrw4Pi4oceciZsmVNE5LR8WaGvC4du2RzMXsoiL8mAqcTH4G1Cpt1mMtrx2oC9yoFLPcU5W | D27: success | E27: atomic flash arb | F27: Jupiter | G27: PYUSD +6.3869 | H27: 6.386879 | I27: 0.001025233 | J27: =H27-I27 -> 6.3858538
A28: solana | B28: 2026-08-30T23:07:38 | C28: 2Vdee9JyS5tERx93WBTP9Xoa7WBTB7Q4DD1iV8JW2mQ3oEvGeDC13MRDse9nNU8LwNqqdFWsRqRLdfMCgdbcL4HT | D28: success | E28: atomic flash arb | F28: Jupiter | G28: PYUSD +0.4991 | H28: 0.499099 | I28: 0.0010042725 | J28: =H28-I28 -> 0.49809473
A29: solana | B29: 2026-08-30T23:08:53 | C29: 43gP3ptrroes4e5FjimSAku4BUZvbHUFcpQCJ864zJviEznYrWuS5PG9VUGzPLgPf8XN2113drYZmq5P2oWe4KRh | D29: success | E29: atomic flash arb | F29: Jupiter | G29: PYUSD +6.1347 | H29: 6.134734 | I29: 0.0010259452 | J29: =H29-I29 -> 6.1337081
A30: solana | B30: 2026-08-30T23:11:59 | C30: 2wXRVfbpyLPh5P6kqdr65U9ZX1axjhGWS934xhJ9Wi1cqy4ZByaZcKxDDdzEo1PAQv7H7y2BJ6expGGBku8K4WZu | D30: success | E30: atomic flash arb | F30: Jupiter | G30: PYUSD +5.6987 | H30: 5.698691 | I30: 0.001032559 | J30: =H30-I30 -> 5.6976584
A31: solana | B31: 2026-08-30T23:25:27 | C31: 4GSxq7dJiLeFAypm6EsKMLNQA6NqanbGsN7Br7Ze4Q1ZSj1YAjvwC5NA68oQC6xjPdHTDrfPJs5kJ8pRa1Fmu7mR | D31: success | E31: atomic flash arb | F31: Jupiter | G31: PYUSD +4.6382 | H31: 4.638247 | I31: 0.0010452778 | J31: =H31-I31 -> 4.6372017
A32: solana | B32: 2026-08-30T23:34:13 | C32: 3Ui9hKvApKfarG21QhbRnCi3KjLVzykgqvdXRXn6GCWogmp8n6hCX2m6YwXm8VQZFrZ6pcb9ciVGGf6q51TMuPQS | D32: success | E32: atomic flash arb | F32: Jupiter | G32: PYUSD +0.8809 | H32: 0.880893 | I32: 0.0010099705 | J32: =H32-I32 -> 0.87988303
A33: solana | B33: 2026-08-31T00:03:43 | C33: 3njy2ZrVBPrnY61nsoCK46nuQddKgmTZZdJw19b6oWvAuD8W8v11xpm7dgHzPAhcZrxSvVmMRyX1crKzENFFL9xY | D33: success | E33: atomic flash arb | F33: Jupiter | G33: PYUSD +3.2262 | H33: 3.226209 | I33: 0.0010385402 | J33: =H33-I33 -> 3.2251705
A34: solana | B34: 2026-08-31T00:19:17 | C34: 2WY4aZwK6VdjRwDNV9gRVJiqrAR5WGvp3bnhdxxfpcduZLtqpWAGw9phxHWijQYZCBz7WPmtXiGxa1ty9bNQgJ7b | D34: success | E34: atomic flash arb | F34: Jupiter | G34: PYUSD +3.3836 | H34: 3.383589 | I34: 0.0010385402 | J34: =H34-I34 -> 3.3825505
A35: solana | B35: 2026-08-31T00:20:33 | C35: 3xPzAmmcs5kCmd3oeyPb7cF8uQ3GUNAkatUPtFzPq8xcfY6qX3KDMnLJvJh8vX6gPoFE4GXFhwFNgSeHrNp99aaE | D35: success | E35: atomic flash arb | F35: Jupiter | G35: PYUSD +1.1800 | H35: 1.18002 | I35: 0.0010395706 | J35: =H35-I35 -> 1.1789804
A36: solana | B36: 2026-08-31T00:26:10 | C36: ZDH2gP8FCP1Ssuqcir6g6VDLDg29Ewp3QJk4AuCq1b928KqxptwZjyY1pEEf16ZjNVm8n9xAi9X3Gztfm8nTFbb | D36: success | E36: atomic flash arb | F36: Jupiter | G36: PYUSD +3.0482 | H36: 3.048191 | I36: 0.0010388493 | J36: =H36-I36 -> 3.0471522
A37: solana | B37: 2026-08-31T00:28:51 | C37: 5imZktXZ5Kn4N6kYJGuZ4UnC3UcCUqAtuAzug9EmkSQtmtzffemHD25XEH4aZBk8EKvtKLZS1o7NdbdLVa7zSu6R | D37: success | E37: atomic flash arb | F37: Jupiter | G37: PYUSD +2.7977 | H37: 2.79771 | I37: 0.0010582208 | J37: =H37-I37 -> 2.7966518
A38: solana | B38: 2026-08-31T00:39:11 | C38: Ha9w1o2Wt5phJXGkTgMbDgzNq87cXamad6Pmwht2cyMju5vZNr7uBooFkrU28moxsj48rqYbNyUvy9uXVkZ4iJP | D38: success | E38: atomic flash arb | F38: Jupiter | G38: PYUSD +2.6238 | H38: 2.623799 | I38: 0.0010388493 | J38: =H38-I38 -> 2.6227602
... A77: solana | B77: 2026-09-03T11:07:25 | C77: 3kNdnmFg8g4AB9X19aRP63YXSTGo8LmJESjXTmmo6c6mbwGNgH9Ka3ifV5QM7C97hb4muszh2uFAaseDeRqS84eD | D77: success | E77: atomic wallet arb | F77: 0x | G77: PYUSD +1.8430 | H77: 1.843013 | I77: 0.0009526101 | J77: =H77-I77 -> 1.8420604
A78: solana | B78: 2026-09-03T12:31:51 | C78: w4BF4gaWF26jF3dyZYMCeyxymWMH3acgkju4AcitRZdub3minnubeJi6E6YTtHWxxL8rM5igXEMwd8zrjZBqLFE | D78: failed | E78: atomic wallet arb | F78: 0x | H78: 0 | I78: 0.0010433497 | J78: =H78-I78 -> -0.0010433497
A79: solana | B79: 2026-09-03T12:32:33 | C79: 36T53fDqS1RsT5eYbZ14BqvQoUwXFTzVnxmoRCGpZa8Uw9YKMpvtudWZvpqF7iJ3mVuWi84zmbAtMLV96q68Hzsg | D79: success | E79: atomic wallet arb | F79: 0x | G79: PYUSD +1.7738 | H79: 1.773831 | I79: 0.0010355542 | J79: =H79-I79 -> 1.7727954
A80: solana | B80: 2026-09-03T12:34:42 | C80: 3BCsHArjntQNGo4k27hbUKPRCVMUcryanboPk2kR2BSfMRLuNo5smUn1fVQcs1hzBMdSRgJoGeA1eckeGY3rTCXE | D80: success | E80: atomic wallet arb | F80: 0x | G80: PYUSD +2.2127 | H80: 2.21273 | I80: 0.0010057234 | J80: =H80-I80 -> 2.2117243
A81: solana | B81: 2026-09-03T12:49:09 | C81: 575F82LAVZfRwFGgQ9crXTdimDXX6z8PFQLVRcANETmV8DCKEX1Piq8NPXwGrk123Ro549x92nEEUaU9ZaC6bwMb | D81: success | E81: atomic wallet arb | F81: 0x | G81: PYUSD +1.1950 | H81: 1.194973 | I81: 0.0010373212 | J81: =H81-I81 -> 1.1939357
A82: solana | B82: 2026-09-03T18:09:49 | C82: 2Vzj7arTHHuxSsFerrwHpEjV7kbDpnZBnM27E6ouoe1PQU74bHiUFT1jafXvZv8NdnfZ9bV2kLLPU6j2zEqGqpdN | D82: success | E82: atomic wallet arb | F82: 0x | G82: PYUSD +5.8775 | H82: 5.87748 | I82: 0.001022146 | J82: =H82-I82 -> 5.8764579
A83: solana | B83: 2026-09-03T18:10:42 | C83: 5fJnfyryXH87Zcb4R8wV7itpEqRieLKAkUs1z9dkHzsbtKpy2iRECg4UStfhtV26NJyxr5bGz16sVo6WE2wRANp3 | D83: success | E83: atomic wallet arb | F83: 0x | G83: PYUSD +6.7094 | H83: 6.709401 | I83: 0.001009985 | J83: =H83-I83 -> 6.708391
A84: solana | B84: 2026-09-03T18:13:18 | C84: 2Ln7tAWEV5uNnE3zz5Lkey66sDoJuXt4FRmwLpYFvp1AZMicpDrhgHQAgAZU5qXeZyAWXamKqPo4npfYbipRgdWo | D84: success | E84: atomic wallet arb | F84: 0x | G84: PYUSD +2.6133 | H84: 2.613336 | I84: 0.00099231518 | J84: =H84-I84 -> 2.6123437
...

Sheet SOL non-atomic legs
A1: chain | B1: time_utc | C1: tx | D1: status | E1: category | F1: provider | G1: detail | H1: stable_gain_usd | I1: fee_usd | J1: net_usd
A2: solana | B2: 2026-06-24T19:29:36 | C2: 2K1N2oGwhbAsC32gmw7YPJtM4EwoU8PsABeJ7eqkrUAbo1SWruZxjnnHxkVw4oPFg2Yvs3mR9PTTa3eCUrnoz2nJ | D2: success | E2: non-atomic leg | F2: 0x | G2: USDC -99,898.6054, USDT +100,013.6856 | H2: 115.08014 | I2: 0.27779093 | J2: =H2-I2 -> 114.80235
A3: solana | B3: 2026-06-24T19:31:08 | C3: WDRgSo5KN38QBcfQQi7WgFrCw3tvWCU495KqTfifdbTfs2FcgJqSyr9nQbJSWJusS7nf1ZcLHupqkmmL11wpivE | D3: success | E3: non-atomic leg | F3: Stable.com | G3: USDT -100,023.6846, USDC +99,923.6609 | H3: -100.02368 | I3: 0.068502392 | J3: =H3-I3 -> -100.09219
A4: solana | B4: 2026-06-24T19:31:20 | C4: 2cWK6iwUjECnsnfaNth1hfPW9DW4xWermaCDkJtgTDwPX12rudnnwAK57qT41KjBYiU1UUhEVwfdpvQTUA9LRCfv | D4: success | E4: non-atomic leg | F4: 0x | G4: USDC -99,923.6609, USDT +100,038.5505 | H4: 114.88962 | I4: 0.00040806 | J4: =H4-I4 -> 114.88921
A5: solana | B5: 2026-06-24T19:31:57 | C5: LgkWaaXtRhH1D6gnXn2KABeiMNibKek8g5CmDGDAcA3axwfq25otWknYan5uakyXzBVJga2uh9NmLDgGej4CsTr | D5: success | E5: non-atomic leg | F5: Stable.com | G5: USDT -100,038.5505, USDC +99,938.5120 | H5: -100.03855 | I5: 0.00034005 | J5: =H5-I5 -> -100.03889
A6: solana | B6: 2026-06-24T19:32:18 | C6: 3iv72iL3aBwS2pb6zT26hbswMHGL555sC14T1MXUN56W87v3cZnqh6DBPykcrSKMkhQizTyJ6PFZidvYBsUEVPV6 | D6: success | E6: non-atomic leg | F6: Jupiter | G6: USDT +100,053.2339, USDC -99,938.5120 | H6: 114.72195 | I6: 0.00040806 | J6: =H6-I6 -> 114.72154
A7: solana | B7: 2026-06-24T19:33:05 | C7: 2xcTFnkFE64BPoYx7zmUA9jrEnnBMz3nXmVjkF76SJRS1Dk83XWrmct6jX45QvPaTCwL5rvzLFUiSaY1oaBbecHP | D7: success | E7: non-atomic leg | F7: Stable.com | G7: USDT -100,053.2339, USDC +99,953.1807 | H7: -100.05323 | I7: 0.00034005 | J7: =H7-I7 -> -100.05357
A8: solana | B8: 2026-06-24T19:33:55 | C8: 3VScb7g5gpFLR8kaS5ELmYf7aj9vkvbjtNPj1gkUqp6cVCGz4usmAfh6YgX4Rb12CjpN5Jz7tDTf2waZEpZXBxaT | D8: failed | E8: non-atomic leg | F8: OKX | H8: 0 | I8: 0.00040806 | J8: =H8-I8 -> -0.00040806
A9: solana | B9: 2026-06-24T19:34:10 | C9: 2wptiPxhHbG4wNZ7V2EM6rB9WTe6wXM4WpaEMSdJJkhXv1KBPz42cy8taUdTZpPCqvDCDJRrq438HubQvk2bVhzY | D9: failed | E9: non-atomic leg | F9: DFlow | H9: 0 | I9: 0.00040806 | J9: =H9-I9 -> -0.00040806
A10: solana | B10: 2026-06-24T19:34:19 | C10: 4hiVnWVkhLLyLa2JFTmiJPRa9PjMNwgZyvpkP3BZNJn6MZBqfTDiw1Zh7ySEFtaHMVNQkbDpKkyjVdC6D4GRA5Zp | D10: success | E10: non-atomic leg | F10: DFlow | G10: USDT +100,066.5579, USDC -99,953.1807 | H10: 113.37716 | I10: 0.00040806 | J10: =H10-I10 -> 113.37675
A11: solana | B11: 2026-06-24T19:34:51 | C11: ym6h21xanbc35T2muSg3JFJYqXKiTz8cewAmbKqpVcoKvhjrmVQ1jBWk7cyrskjFGTgsQyAYGs9pQ36PeXFAuR5 | D11: success | E11: non-atomic leg | F11: Stable.com | G11: USDT -100,066.5579, USDC +99,966.4913 | H11: -100.06656 | I11: 0.00034005 | J11: =H11-I11 -> -100.0669
A12: solana | B12: 2026-06-24T19:35:10 | C12: 3piH9LXCoT4DykyUgvdPTrBnEGrL3PokHJBKsGTog7UB6Ahm3HQabfPE3FEMtppdULVyHuKGFwFAYFPL9CMQNADF | D12: success | E12: non-atomic leg | F12: DFlow | G12: USDT +100,081.2543, USDC -99,966.4913 | H12: 114.76295 | I12: 0.00040806 | J12: =H12-I12 -> 114.76255
A13: solana | B13: 2026-06-24T19:41:15 | C13: 4QxCDrBCrZbvJjNnDZFyLVeQLfKvfo4bpCASoFDkn4QcBUKaXu5DkpbCwx7W2u2wqXA8uvjHJXMfTetRUjMThEHm | D13: success | E13: non-atomic leg | F13: Stable.com | G13: USDT -100,081.2543, USDC +99,981.1730 | H13: -100.08125 | I13: 0.00034005 | J13: =H13-I13 -> -100.08159
A14: solana | B14: 2026-06-24T19:41:34 | C14: 3NBGUhXfsQPBNaPmBozWQSp7DwBuawxTv7Hx11KKYaMzksbCviPqwFFpD8xyhWZqtbeG1sUCGgPJ7DRWBVmwfDsn | D14: success | E14: non-atomic leg | F14: OKX | G14: USDT +100,097.6427, USDC -99,981.1730 | H14: 116.46968 | I14: 0.00040806 | J14: =H14-I14 -> 116.46927
A15: solana | B15: 2026-06-24T19:42:00 | C15: 29gUbsYK18niwpqcqnoA4bqnNkVTbGNW2otwqoXMB8Gs1doFik1BJPiZHtL4jmqwsQxr1EoPh8tgPdDAbejr6Xif | D15: success | E15: non-atomic leg | F15: Stable.com | G15: USDT -44,998.0000, PYUSD +44,953.0020 | H15: -44.998 | I15: 0.14944517 | J15: =H15-I15 -> -45.147445
A16: solana | B16: 2026-06-24T19:42:12 | C16: 5bsWkw9Fsdp7hEgaDT9g5ngTtu7q61fBWjB1C2e9Rh8H3iM89cDWw56fb2aiCcevaYPRonNCcx7kpa6iMohCjmzf | D16: success | E16: non-atomic leg | F16: OKX | G16: USDT +45,006.4601, PYUSD -44,953.0020 | H16: 53.458054 | I16: 0.00040806 | J16: =H16-I16 -> 53.457646
A17: solana | B17: 2026-06-26T10:42:09 | C17: 5xdagLv1Mnn4QVCyhYj8e5YgXAqqTmVo6yH9oTGcVxerR5apCBFbQuJ6tJuFXzzRVY8minSScuqZqxFiUWmaB4pT | D17: success | E17: non-atomic leg | F17: OKX | G17: USDT +100,128.7302, USDC -100,016.3119 | H17: 112.4183 | I17: 0.00043074 | J17: =H17-I17 -> 112.41787
A18: solana | B18: 2026-06-26T10:44:35 | C18: H6GfffB8rKGr74gVbL5XzszDTyYhtcNqYLa5hfTmFs5Braym5wGLeN3s1FLDMazQD2xEtHykxiCskX1rbDSP1Vh | D18: success | E18: non-atomic leg | F18: Stable.com | G18: USDT -39,998.0000, PYUSD +39,958.0020 | H18: -39.998 | I18: 0.00035895 | J18: =H18-I18 -> -39.998359
A19: solana | B19: 2026-06-26T10:45:02 | C19: 4nZeDSpWvLBqbnzn5mtRQtqKDxG9Kwf2CEr9Q5gDFxqJ4tjzJS2ax8SZNYNdpJKfNGMM8Tbvr6s9RfiSary2EK3t | D19: success | E19: non-atomic leg | F19: OKX | G19: USDT +40,007.3003, PYUSD -39,958.0020 | H19: 49.29833 | I19: 0.00043074 | J19: =H19-I19 -> 49.297899
A20: solana | B20: 2026-06-26T10:45:50 | C20: 3pMorWAF2C3TBbqU76vFEQEmEiWoqYx6KT6zf2nECE2UB3n2QrczHiACJy6mpfmSP1bbUyu7kKwCocnpFsFT8f48 | D20: success | E20: non-atomic leg | F20: Stable.com | G20: USDT -100,138.0305, USDC +100,037.8925 | H20: -100.13803 | I20: 0.00035895 | J20: =H20-I20 -> -100.13839
A21: solana | B21: 2026-06-26T10:46:06 | C21: 2F7NqRCU9toTnzChayZRjL8k9CvQUe7n43Cb4LGx7qzxPQTbjbNothmvJbtZWfyp9NX34xKHKdHvaNzg7TJPJBLe | D21: success | E21: non-atomic leg | F21: 0x | G21: USDC -100,037.8925, USDT +100,149.0123 | H21: 111.11978 | I21: 0.14683065 | J21: =H21-I21 -> 110.97295
... A31: solana | B31: 2026-06-27T05:40:10 | C31: 3BmCPHLHXbyubUk65qr6mXWDpV3Wmv7xWbRNb8Ab4A6Jgve5hipdqiRsu2nzjdYwF9wNHFPBbumj3MBMx3TUukE2 | D31: success | E31: non-atomic leg | F31: Stable.com | G31: USDG +9,990.0000, USDT -10,000.0000 | H31: -10 | I31: 0.15467499 | J31: =H31-I31 -> -10.154675
A32: solana | B32: 2026-06-27T05:40:22 | C32: 31VtnBYvy4grfg2yY2b1kG9W6eHawabEUKxgJTYEhwKQd7hv97545zr2zwtUZCAkgL7zyxi6hkb5z6bH8M7TRGKv | D32: failed | E32: non-atomic leg | F32: Jupiter | H32: 0 | I32: 0.0014078 | J32: =H32-I32 -> -0.0014078
A33: solana | B33: 2026-06-27T05:40:41 | C33: 2QWKeSQN6R2pBzfpCeFfnpafzRyG3341FDdbKu5e2eGPZEHkv38XhGibw87oA8o17Mm1hTkBpU5fsfGRSYPxkzyg | D33: failed | E33: non-atomic leg | F33: Jupiter | H33: 0 | I33: 0.00057677566 | J33: =H33-I33 -> -0.00057677566
A34: solana | B34: 2026-06-27T05:40:44 | C34: 438RT4EyKjqMJfSvn2sJDS14yu5QSKL48thnrnhBTeF8VLmdNQNkCCc3rZ1jDqug1KaFwhPPjy6YUdQVgBdhBtFg | D34: failed | E34: non-atomic leg | F34: Jupiter | H34: 0 | I34: 0.00052468706 | J34: =H34-I34 -> -0.00052468706
A35: solana | B35: 2026-06-27T05:40:48 | C35: 45A3DYGRqVHSfK8ZD5iDWAjteaqypq94FofNKkG5CHRtYmSwCa2dJFNTBiUSzixo632LaSirtVJMxfnkiqTNwvET | D35: failed | E35: non-atomic leg | F35: Jupiter | H35: 0 | I35: 0.0004336024 | J35: =H35-I35 -> -0.0004336024
A36: solana | B36: 2026-06-27T05:40:53 | C36: 5u67idb2Cu2sAc7f6KRHvkGYjwGier5bMNPgnzBRba6ZJLhKNHZidaRqUqWqSYdQyo2aEQA1b4dDV6oFbp9VT2Uw | D36: success | E36: non-atomic leg | F36: Jupiter | G36: USDT +1,000.0286, USDC -998.9132 | H36: 1.115403 | I36: 0.00098947223 | J36: =H36-I36 -> 1.1144135
A37: solana | B37: 2026-06-27T05:41:07 | C37: 36NF9UMHvNnRTdFDfSzvNkDLNgNtfFtDXuqAKz7RfuZtrGPssn1mefZwuhrr6BfePDWiUkCj9SCy1KpDpc7cRqwT | D37: success | E37: non-atomic leg | F37: Jupiter | G37: USDT +1,000.0561, USDC -998.9407 | H37: 1.115436 | I37: 0.0053960974 | J37: =H37-I37 -> 1.1100399
A38: solana | B38: 2026-06-27T05:41:34 | C38: 2k3dDFfPoyw9VExqk5Rkqaje7vu5wGrffFZqc6BrPqXgDcoHpSijSTtqcLH1GYqZYEnk6ByjZByo8hrDELCcWNdL | D38: failed | E38: non-atomic leg | F38: Jupiter | H38: 0 | I38: 0.00059022015 | J38: =H38-I38 -> -0.00059022015
A39: solana | B39: 2026-06-27T05:41:38 | C39: 2uj5M9iQ9grjRCVw37ncPPNi1vMizxyyo3Rwsew8Fcj739nEJX8exG76A2BCBLkYGDMDQ9CHneJkmgCy4HUjFqTm | D39: success | E39: non-atomic leg | F39: Jupiter | G39: USDT +1,000.0840, USDC -998.9678 | H39: 1.116198 | I39: 0.0010813312 | J39: =H39-I39 -> 1.1151167
A40: solana | B40: 2026-06-27T05:41:47 | C40: 5Md5JX9jWkXXMk1vdk2o6UchXRGjBYRjpWRrAqxGvQ2PqrJ4F6y5sez4wakqw1LTi3eYN2PhCrTrZSkfRKCVLebG | D40: failed | E40: non-atomic leg | F40: Jupiter | H40: 0 | I40: 0.00095181358 | J40: =H40-I40 -> -0.00095181358
A41: solana | B41: 2026-06-27T05:46:02 | C41: 61VtvrouLMdJY2SeL9PmN8kceiDxyaDXf8vuZdf4cDt9oDSb16mWnoUidsAmZ78A7yy5WQioKfEySawjPtD95SEr | D41: failed | E41: non-atomic leg | F41: Jupiter | H41: 0 | I41: 0.00036940672 | J41: =H41-I41 -> -0.00036940672
A42: solana | B42: 2026-06-27T05:46:03 | C42: 42UquMGmevBytFFpu51VrB4uSGSNQJiQuZEZPg9LTKLpKAq753h4Lo8wotEyExGq5yCFgyed2RdXw5uY5FLThetC | D42: failed | E42: non-atomic leg | F42: Jupiter | H42: 0 | I42: 0.00105585 | J42: =H42-I42 -> -0.00105585
A43: solana | B43: 2026-06-27T05:46:06 | C43: 5WC5HsCimFLDieANUoqp789GYXxAT5m1exCnu9oZejEmfeZSPHpK6Y67QTWe12wnTTo969sebPrzzVecrm8mnXUC | D43: success | E43: non-atomic leg | F43: Jupiter | G43: USDT +1,000.1130, USDC -998.9958 | H43: 1.117129 | I43: 0.0017576383 | J43: =H43-I43 -> 1.1153714
A44: solana | B44: 2026-06-27T05:46:13 | C44: 5JJew2XAhpi4vgAeK9itxMnjujy4PMBBVmnLwP5oDyZKS2uVvkeRnAWB29HeaG5NR6Aoqpc6aY5uhvWZt5VZdnqz | D44: success | E44: non-atomic leg | F44: Jupiter | G44: USDT +1,000.1203, USDC -999.0042 | H44: 1.116184 | I44: 0.0013501506 | J44: =H44-I44 -> 1.1148338
A45: solana | B45: 2026-06-27T05:46:30 | C45: iPTZBNu8uHCgAot5Q4K1XH8cuzeJ7rGPnrSx8VsEa8HTcLRrwuKAhFxeRNVhZB1ibYPq6aNJ614ywdGbcUn1mBc | D45: failed | E45: non-atomic leg | F45: Jupiter | H45: 0 | I45: 0.0014078 | J45: =H45-I45 -> -0.0014078
A46: solana | B46: 2026-06-27T05:46:32 | C46: 3RnWP4hMjTd4KX6aor9P5wnd4QmdjSF9zcdUqtbHxN4N3Vyqr3vxkc41EAprCFncUMM67jpYyF2445RviTTjn4tc | D46: failed | E46: non-atomic leg | F46: Jupiter | H46: 0 | I46: 0.0014078 | J46: =H46-I46 -> -0.0014078
A47: solana | B47: 2026-06-27T05:46:33 | C47: 4NuTwLN27gV1VCJC9DW65z1feUnPiGgr5LNwYehrMyxENQA34SnmdQBj6bGYhQMpxzprhHaj6gDyxdkNgFPHggCu | D47: success | E47: non-atomic leg | F47: Jupiter | G47: USDG -9,990.0000, USDT +10,001.9020 | H47: 11.901964 | I47: 0.0016396647 | J47: =H47-I47 -> 11.900324
A48: solana | B48: 2026-06-27T05:46:51 | C48: 4AUFkt72juMHaJUH1mRGhppcdUQJbK3unUD2CPJbowXceroE3mnypkjrRh7BkKiqTkysNCMnNyqvKi4qddZq2Pfs | D48: success | E48: non-atomic leg | F48: Jupiter | G48: USDT +1,000.0109, USDC -998.8902 | H48: 1.120722 | I48: 0.0012442136 | J48: =H48-I48 -> 1.1194778
A49: solana | B49: 2026-06-27T05:46:53 | C49: 5xmAnPjpYAHvG8d7KvgHUP2v8MuWVHQUN4uuLs6Nhb24Gumzh16vCL561WTAMWQ9oYH8kBwF5UqxWoi4UNPB747n | D49: success | E49: non-atomic leg | F49: Jupiter | G49: USDT -1,000.0109, USDC +998.8884 | H49: -1.122466 | I49: 0.0012990474 | J49: =H49-I49 -> -1.123765
...
